Workbook

Sheet 使用说明
A1: 仓库规划库存需求计算模板 — 使用说明
A3: 【工作簿结构】
B4: 使用说明 | C4: 本页面，说明各工作表用途及填写方法。
B5: 参数设置 | C5: 填写全局通用参数：年工作天数、安全系数、托盘尺寸、面积利用率等。
B6: 产品SKU | C6: 逐行输入每个产品/SKU 的需求与生产参数（年需求量、最小批量、生产间隔、成品目标库存天数等）。
B7: 原料BOM | C7: 填写产品-原料消耗矩阵，每行一种原料，列对应各SKU，输入单位消耗量及累计良率损耗系数。
B8: 原料仓计算 | C8: 自动按原料汇总日消耗量，并计算： 设计库存 = MAX(日消耗×采购提前期, 最小订购量) + 安全库存 + 下批备料库存 + 退料库存 + 待检库存。
B9: 过程品仓计算 | C9: 按工序位置和SKU 计算： 设计WIP = MAX(下游小时消耗×缓冲小时数, 批量×最大等待批次数) + 待检库存 + 尾批库存 + 不良/返工库存。
B10: 成品仓计算 | C10: 按SKU 计算： 设计库存 = MAX(日需求×生产间隔, 日需求×目标库存天数, 最小生产批量) + 安全库存 + 待检放行库存。
B11: 汇总 | C11: 汇总三类仓库的设计库存量，并可选择计算托盘数和估算面积。
A13: 【填写说明】
B14: 蓝色单元格 | C14: 用户需要手动输入的参数（深蓝色字体、浅蓝色底色）。
B15: 绿色单元格 | C15: 由公式自动计算，请勿手动修改（黑色字体、浅绿色底色）。
B16: 黄色单元格 | C16: 关键假设，需要特别关注和确认。
B17: 行数扩展 | C17: 各计算表预留了足够行数（最多20行），需要更多行时可复制最后一行的公式向下填充。
A19: 【计算逻辑说明】
B20: 原料仓 | C20: 库存 = MAX(日均消耗×采购提前期天数, 最小订购量MOQ) + 安全库存 + 下一批次备料库存 + 换产退料库存 + 待检库存
B21: 过程品仓 | C21: 库存 = MAX(下游小时消耗×缓冲小时数, 批量大小×最大等待批次数) + 待检等待库存 + 尾批库存 + 不良品/返工/隔离库存
B22: 成品仓 | C22: 库存 = MAX(日需求量×生产间隔天数, 日需求量×目标库存天数, 最小生产批量) + 安全库存天数×日需求量 + 待检放行库存
B23: 面积估算 | C23: 仓库面积 = 库存量 ÷ 每托盘装载量 × 单托盘占地面积 ÷ 堆码层数 ÷ 面积利用率
A25: 【注意事项】
B26: 多SKU换产 | C26: 换产时会产生剩余退料（原料未用完退回），退料库存已在原料仓计算中单独考虑。
B27: 良率损耗 | C27: BOM 表中需填写累计良率损耗系数（如工序1×工序2×工序3的综合良率倒数），以反映从原料到成品的实际消耗。
B28: 安全系数 | C28: 参数设置中的安全系数会乘以基础库存量，建议原料仓1.1~1.3，过程品仓1.1~1.2，成品仓1.1~1.2。
B29: 数量单位 | C29: 本表不限定单位，请在各表表头的单位列中注明所使用的单位（件、箱、吨、kg等），并保持全表一致。

Sheet 参数设置
A1: 参数设置 — 全局通用参数
B2: 参数名称 | C2: 数值 | D2: 单位 | E2: 说明
B3: 【生产基础参数】
B4: 年工作天数 | C4: 300 | D4: 天/年 | E4: 全年实际生产工作日，常用250~300天
B5: 每天工作小时数 | C5: 20 | D5: 小时/天 | E5: 含加班，用于计算小时产能
B6: 年工作小时数 | C6: =参数设置!C4*参数设置!C5 | D6: 小时/年 | E6: 自动计算 = 年工作天数 × 每天工作小时数
B7: 默认安全系数（原料仓） | C7: 1.2 | D7: — | E7: 库存量乘以该系数以应对波动，建议1.1~1.3
B8: 默认安全系数（过程品仓） | C8: 1.15 | D8: — | E8: 建议1.1~1.2
B9: 默认安全系数（成品仓） | C9: 1.2 | D9: — | E9: 建议1.1~1.2
B10: 【托盘与存储参数】
B11: 标准托盘长度 | C11: 1.2 | D11: m | E11: 常用1.0m或1.2m
B12: 标准托盘宽度 | C12: 1 | D12: m | E12: 常用0.8m或1.0m
B13: 单托盘占地面积 | C13: =参数设置!C11*参数设置!C12 | D13: m²/托 | E13: 自动计算 = 长 × 宽
B14: 地堆层数 | C14: 2 | D14: 层 | E14: 无货架时地面堆叠层数
B15: 货架层数（如有） | C15: 4 | D15: 层 | E15: 有货架时使用货架层数，无货架填0
B16: 【面积利用率参数】
B17: 原料仓面积利用率 | C17: 0.45 | D17: — | E17: 通常35%~60%，含通道/叉车/消防等
B18: 过程品仓面积利用率 | C18: 0.5 | D18: — | E18: 通常40%~60%
B19: 成品仓面积利用率 | C19: 0.5 | D19: — | E19: 通常40%~60%
B20: 【扩展余量】
B21: 面积扩展余量系数 | C21: 1.2 | D21: — | E21: 最终面积乘以该系数，预留10%~30%余量
B23: ★ 其他工作表通过[参数设置!C行号]引用本表数值，请勿删除或移动行。

Sheet 产品SKU
A1: 产品SKU — 产品级输入参数
A2: 行号 | B2: 产品编号/SKU | C2: 产品名称 | D2: 单位 | E2: 年需求量 (件/年) | F2: 月需求量 (件/月) [自动] | G2: 日需求量 (件/天) [自动] | H2: 最小生产 批量(件) | I2: 生产间隔 (天) | J2: 目标成品 库存天数 | K2: 安全库存 天数 | L2: 待检等待 天数 | M2: 成品每托 装载量(件) | N2: 单件重量 (kg) | O2: 过程品缓冲 小时数 (工序1后) | P2: 过程品缓冲 小时数 (工序2后) | Q2: 过程品缓冲 小时数 (工序3后) | R2: 备注
A3: 1 | B3: SKU-001 | C3: 产品A | D3: 件 | E3: 120000 | F3: =IFERROR(产品SKU!E3/12,"") | G3: =IFERROR(产品SKU!E3/参数设置!$C$4,"") | H3: 5000 | I3: 7 | J3: 14 | K3: 3 | L3: 2 | M3: 50 | N3: 0.5 | O3: 4 | P3: 6 | Q3: 8
A4: 2 | B4: SKU-002 | C4: 产品B | D4: 件 | E4: 96000 | F4: =IFERROR(产品SKU!E4/12,"") | G4: =IFERROR(产品SKU!E4/参数设置!$C$4,"") | H4: 4000 | I4: 7 | J4: 14 | K4: 3 | L4: 2 | M4: 40 | N4: 0.6 | O4: 4 | P4: 6 | Q4: 8
A5: 3 | B5: SKU-003 | C5: 产品C | D5: 件 | E5: 72000 | F5: =IFERROR(产品SKU!E5/12,"") | G5: =IFERROR(产品SKU!E5/参数设置!$C$4,"") | H5: 3000 | I5: 10 | J5: 15 | K5: 4 | L5: 2 | M5: 30 | N5: 0.8 | O5: 3 | P5: 5 | Q5: 7
A6: 4 | B6: SKU-004 | C6: 产品D | D6: 件 | E6: 60000 | F6: =IFERROR(产品SKU!E6/12,"") | G6: =IFERROR(产品SKU!E6/参数设置!$C$4,"") | H6: 3000 | I6: 10 | J6: 15 | K6: 4 | L6: 2 | M6: 60 | N6: 0.4 | O6: 3 | P6: 5 | Q6: 7
A7: 5 | B7: SKU-005 | C7: 产品E | D7: 件 | E7: 48000 | F7: =IFERROR(产品SKU!E7/12,"") | G7: =IFERROR(产品SKU!E7/参数设置!$C$4,"") | H7: 2000 | I7: 14 | J7: 20 | K7: 5 | L7: 3 | M7: 50 | N7: 0.5 | O7: 4 | P7: 6 | Q7: 8
A8: 6 | B8: SKU-006 | C8: 产品F | D8: 件 | E8: 36000 | F8: =IFERROR(产品SKU!E8/12,"") | G8: =IFERROR(产品SKU!E8/参数设置!$C$4,"") | H8: 2000 | I8: 14 | J8: 20 | K8: 5 | L8: 3 | M8: 40 | N8: 0.7 | O8: 4 | P8: 6 | Q8: 8
A9: 7 | B9: SKU-007 | C9: 产品G | D9: 件 | E9: 24000 | F9: =IFERROR(产品SKU!E9/12,"") | G9: =IFERROR(产品SKU!E9/参数设置!$C$4,"") | H9: 1500 | I9: 21 | J9: 21 | K9: 7 | L9: 3 | M9: 30 | N9: 1 | O9: 3 | P9: 5 | Q9: 7
A10: 8 | B10: SKU-008 | C10: 产品H | D10: 件 | E10: 18000 | F10: =IFERROR(产品SKU!E10/12,"") | G10: =IFERROR(产品SKU!E10/参数设置!$C$4,"") | H10: 1500 | I10: 21 | J10: 21 | K10: 7 | L10: 3 | M10: 25 | N10: 1.2 | O10: 3 | P10: 5 | Q10: 7
A11: 9 | F11: =IFERROR(产品SKU!E11/12,"") | G11: =IFERROR(产品SKU!E11/参数设置!$C$4,"")
A12: 10 | F12: =IFERROR(产品SKU!E12/12,"") | G12: =IFERROR(产品SKU!E12/参数设置!$C$4,"")
A13: 11 | F13: =IFERROR(产品SKU!E13/12,"") | G13: =IFERROR(产品SKU!E13/参数设置!$C$4,"")
A14: 12 | F14: =IFERROR(产品SKU!E14/12,"") | G14: =IFERROR(产品SKU!E14/参数设置!$C$4,"")

Sheet 原料BOM
A1: 原料BOM — 产品-原料消耗矩阵
A2: 填写说明：对应单元格填写每生产1件该SKU成品所消耗的该原料数量(已含良率损耗)，单位须与原料仓计算中一致；若该SKU不使用该原料，填0或留空。
A3: 行号 | B3: 原料编号 | C3: 原料名称 | D3: 单位 | E3: =IFERROR(产品SKU!B3,"SKU-01") | F3: =IFERROR(产品SKU!B4,"SKU-02") | G3: =IFERROR(产品SKU!B5,"SKU-03") | H3: =IFERROR(产品SKU!B6,"SKU-04") | I3: =IFERROR(产品SKU!B7,"SKU-05") | J3: =IFERROR(产品SKU!B8,"SKU-06") | K3: =IFERROR(产品SKU!B9,"SKU-07") | L3: =IFERROR(产品SKU!B10,"SKU-08") | M3: =IFERROR(产品SKU!B11,"SKU-09") | N3: =IFERROR(产品SKU!B12,"SKU-10") | O3: =IFERROR(产品SKU!B13,"SKU-11") | P3: =IFERROR(产品SKU!B14,"SKU-12")
A4: 1 | B4: RM-001 | C4: 原料甲 | D4: kg | E4: 1.2 | F4: 1.1 | I4: 0.8 | J4: 0.8
A5: 2 | B5: RM-002 | C5: 原料乙 | D5: kg | E5: 0.5 | G5: 0.6 | H5: 0.6 | K5: 0.4 | L5: 0.4
A6: 3 | B6: RM-003 | C6: 原料丙 | D6: m | E6: 0.3 | F6: 0.3 | G6: 0.3 | I6: 0.3 | K6: 0.3
A7: 4 | B7: RM-004 | C7: 原料丁 | D7: 片 | E7: 2 | F7: 2 | G7: 2 | H7: 2
A8: 5 | B8: RM-005 | C8: 辅料A | D8: g | E8: 5 | F8: 5 | G8: 5 | H8: 5 | I8: 5 | J8: 5 | K8: 5 | L8: 5
A9: 6 | B9: RM-006 | C9: 辅料B | D9: mL | E9: 2 | F9: 2 | G9: 2 | H9: 2 | I9: 2 | J9: 2 | K9: 2 | L9: 2
A10: 7 | B10: RM-007 | C10: 包装材料X | D10: 个 | E10: 1 | F10: 1 | G10: 1 | H10: 1 | I10: 1 | J10: 1 | K10: 1 | L10: 1
A11: 8 | B11: RM-008 | C11: 包装材料Y | D11: 个 | G11: 1 | H11: 1 | I11: 1 | J11: 1 | K11: 1 | L11: 1
A12: 9
A13: 10
A14: 11
A15: 12
A16: 13
A17: 14
A18: 15

Sheet 原料仓计算
A1: 原料仓计算 — 设计库存量
A2: 公式：设计库存 = MAX(日均消耗×采购提前期, MOQ) × 安全系数 + 安全库存 + 下批备料库存 + 换产退料库存 + 待检库存
A3: 行号 | B3: 原料编号 | C3: 原料名称 | D3: 单位 | E3: 日均总消耗量 [自动] | F3: 采购提前期 (天) | G3: 最小订购量 MOQ | H3: 安全系数 | I3: 安全库存量 (件) | J3: 下批备料 库存量 | K3: 换产退料 库存量 | L3: 待检库存量 | M3: 设计库存量 [自动] | N3: 每托盘装量 | O3: 设计托盘数 [自动] | P3: 估算占地面积 (m²)[自动]
A4: 1 | B4: =IFERROR(原料BOM!B4,"") | C4: =IFERROR(原料BOM!C4,"") | D4: =IFERROR(原料BOM!D4,"") | E4: =IFERROR(SUMPRODUCT(原料BOM!E4:P4,产品SKU!$G$3:产品SKU!$G$14),0) | F4: 15 | H4: =参数设置!$C$7 | M4: =IFERROR(MAX(原料仓计算!E4*原料仓计算!F4,IF(原料仓计算!G4="",0,原料仓计算!G4))*原料仓计算!H4+IF(原料仓计算!I4="",0,原料仓计算!I4)+IF(原料仓计算!J4="",0,原料仓计算!J4)+IF(原料仓计算!K4="",0,原料仓计算!K4)+IF(原料仓计算!L4="",0,原料仓计算!L4),0) | O4: =IFERROR(CEILING(原料仓计算!M4/IF(原料仓计算!N4=0,1,原料仓计算!N4),1),0) | P4: =IFERROR(原料仓计算!O4*参数设置!$C$13/MAX(参数设置!$C$14,1)/参数设置!$C$17*参数设置!$C$21,0)
A5: 2 | B5: =IFERROR(原料BOM!B5,"") | C5: =IFERROR(原料BOM!C5,"") | D5: =IFERROR(原料BOM!D5,"") | E5: =IFERROR(SUMPRODUCT(原料BOM!E5:P5,产品SKU!$G$3:产品SKU!$G$14),0) | F5: 15 | H5: =参数设置!$C$7 | M5: =IFERROR(MAX(原料仓计算!E5*原料仓计算!F5,IF(原料仓计算!G5="",0,原料仓计算!G5))*原料仓计算!H5+IF(原料仓计算!I5="",0,原料仓计算!I5)+IF(原料仓计算!J5="",0,原料仓计算!J5)+IF(原料仓计算!K5="",0,原料仓计算!K5)+IF(原料仓计算!L5="",0,原料仓计算!L5),0) | O5: =IFERROR(CEILING(原料仓计算!M5/IF(原料仓计算!N5=0,1,原料仓计算!N5),1),0) | P5: =IFERROR(原料仓计算!O5*参数设置!$C$13/MAX(参数设置!$C$14,1)/参数设置!$C$17*参数设置!$C$21,0)
A6: 3 | B6: =IFERROR(原料BOM!B6,"") | C6: =IFERROR(原料BOM!C6,"") | D6: =IFERROR(原料BOM!D6,"") | E6: =IFERROR(SUMPRODUCT(原料BOM!E6:P6,产品SKU!$G$3:产品SKU!$G$14),0) | F6: 15 | H6: =参数设置!$C$7 | M6: =IFERROR(MAX(原料仓计算!E6*原料仓计算!F6,IF(原料仓计算!G6="",0,原料仓计算!G6))*原料仓计算!H6+IF(原料仓计算!I6="",0,原料仓计算!I6)+IF(原料仓计算!J6="",0,原料仓计算!J6)+IF(原料仓计算!K6="",0,原料仓计算!K6)+IF(原料仓计算!L6="",0,原料仓计算!L6),0) | O6: =IFERROR(CEILING(原料仓计算!M6/IF(原料仓计算!N6=0,1,原料仓计算!N6),1),0) | P6: =IFERROR(原料仓计算!O6*参数设置!$C$13/MAX(参数设置!$C$14,1)/参数设置!$C$17*参数设置!$C$21,0)
A7: 4 | B7: =IFERROR(原料BOM!B7,"") | C7: =IFERROR(原料BOM!C7,"") | D7: =IFERROR(原料BOM!D7,"") | E7: =IFERROR(SUMPRODUCT(原料BOM!E7:P7,产品SKU!$G$3:产品SKU!$G$14),0) | F7: 15 | H7: =参数设置!$C$7 | M7: =IFERROR(MAX(原料仓计算!E7*原料仓计算!F7,IF(原料仓计算!G7="",0,原料仓计算!G7))*原料仓计算!H7+IF(原料仓计算!I7="",0,原料仓计算!I7)+IF(原料仓计算!J7="",0,原料仓计算!J7)+IF(原料仓计算!K7="",0,原料仓计算!K7)+IF(原料仓计算!L7="",0,原料仓计算!L7),0) | O7: =IFERROR(CEILING(原料仓计算!M7/IF(原料仓计算!N7=0,1,原料仓计算!N7),1),0) | P7: =IFERROR(原料仓计算!O7*参数设置!$C$13/MAX(参数设置!$C$14,1)/参数设置!$C$17*参数设置!$C$21,0)
A8: 5 | B8: =IFERROR(原料BOM!B8,"") | C8: =IFERROR(原料BOM!C8,"") | D8: =IFERROR(原料BOM!D8,"") | E8: =IFERROR(SUMPRODUCT(原料BOM!E8:P8,产品SKU!$G$3:产品SKU!$G$14),0) | F8: 15 | H8: =参数设置!$C$7 | M8: =IFERROR(MAX(原料仓计算!E8*原料仓计算!F8,IF(原料仓计算!G8="",0,原料仓计算!G8))*原料仓计算!H8+IF(原料仓计算!I8="",0,原料仓计算!I8)+IF(原料仓计算!J8="",0,原料仓计算!J8)+IF(原料仓计算!K8="",0,原料仓计算!K8)+IF(原料仓计算!L8="",0,原料仓计算!L8),0) | O8: =IFERROR(CEILING(原料仓计算!M8/IF(原料仓计算!N8=0,1,原料仓计算!N8),1),0) | P8: =IFERROR(原料仓计算!O8*参数设置!$C$13/MAX(参数设置!$C$14,1)/参数设置!$C$17*参数设置!$C$21,0)
A9: 6 | B9: =IFERROR(原料BOM!B9,"") | C9: =IFERROR(原料BOM!C9,"") | D9: =IFERROR(原料BOM!D9,"") | E9: =IFERROR(SUMPRODUCT(原料BOM!E9:P9,产品SKU!$G$3:产品SKU!$G$14),0) | F9: 15 | H9: =参数设置!$C$7 | M9: =IFERROR(MAX(原料仓计算!E9*原料仓计算!F9,IF(原料仓计算!G9="",0,原料仓计算!G9))*原料仓计算!H9+IF(原料仓计算!I9="",0,原料仓计算!I9)+IF(原料仓计算!J9="",0,原料仓计算!J9)+IF(原料仓计算!K9="",0,原料仓计算!K9)+IF(原料仓计算!L9="",0,原料仓计算!L9),0) | O9: =IFERROR(CEILING(原料仓计算!M9/IF(原料仓计算!N9=0,1,原料仓计算!N9),1),0) | P9: =IFERROR(原料仓计算!O9*参数设置!$C$13/MAX(参数设置!$C$14,1)/参数设置!$C$17*参数设置!$C$21,0)
A10: 7 | B10: =IFERROR(原料BOM!B10,"") | C10: =IFERROR(原料BOM!C10,"") | D10: =IFERROR(原料BOM!D10,"") | E10: =IFERROR(SUMPRODUCT(原料BOM!E10:P10,产品SKU!$G$3:产品SKU!$G$14),0) | F10: 15 | H10: =参数设置!$C$7 | M10: =IFERROR(MAX(原料仓计算!E10*原料仓计算!F10,IF(原料仓计算!G10="",0,原料仓计算!G10))*原料仓计算!H10+IF(原料仓计算!I10="",0,原料仓计算!I10)+IF(原料仓计算!J10="",0,原料仓计算!J10)+IF(原料仓计算!K10="",0,原料仓计算!K10)+IF(原料仓计算!L10="",0,原料仓计算!L10),0) | O10: =IFERROR(CEILING(原料仓计算!M10/IF(原料仓计算!N10=0,1,原料仓计算!N10),1),0) | P10: =IFERROR(原料仓计算!O10*参数设置!$C$13/MAX(参数设置!$C$14,1)/参数设置!$C$17*参数设置!$C$21,0)
A11: 8 | B11: =IFERROR(原料BOM!B11,"") | C11: =IFERROR(原料BOM!C11,"") | D11: =IFERROR(原料BOM!D11,"") | E11: =IFERROR(SUMPRODUCT(原料BOM!E11:P11,产品SKU!$G$3:产品SKU!$G$14),0) | F11: 15 | H11: =参数设置!$C$7 | M11: =IFERROR(MAX(原料仓计算!E11*原料仓计算!F11,IF(原料仓计算!G11="",0,原料仓计算!G11))*原料仓计算!H11+IF(原料仓计算!I11="",0,原料仓计算!I11)+IF(原料仓计算!J11="",0,原料仓计算!J11)+IF(原料仓计算!K11="",0,原料仓计算!K11)+IF(原料仓计算!L11="",0,原料仓计算!L11),0) | O11: =IFERROR(CEILING(原料仓计算!M11/IF(原料仓计算!N11=0,1,原料仓计算!N11),1),0) | P11: =IFERROR(原料仓计算!O11*参数设置!$C$13/MAX(参数设置!$C$14,1)/参数设置!$C$17*参数设置!$C$21,0)
A12: 9 | B12: =IFERROR(原料BOM!B12,"") | C12: =IFERROR(原料BOM!C12,"") | D12: =IFERROR(原料BOM!D12,"") | E12: =IFERROR(SUMPRODUCT(原料BOM!E12:P12,产品SKU!$G$3:产品SKU!$G$14),0) | H12: =参数设置!$C$7 | M12: =IFERROR(MAX(原料仓计算!E12*原料仓计算!F12,IF(原料仓计算!G12="",0,原料仓计算!G12))*原料仓计算!H12+IF(原料仓计算!I12="",0,原料仓计算!I12)+IF(原料仓计算!J12="",0,原料仓计算!J12)+IF(原料仓计算!K12="",0,原料仓计算!K12)+IF(原料仓计算!L12="",0,原料仓计算!L12),0) | O12: =IFERROR(CEILING(原料仓计算!M12/IF(原料仓计算!N12=0,1,原料仓计算!N12),1),0) | P12: =IFERROR(原料仓计算!O12*参数设置!$C$13/MAX(参数设置!$C$14,1)/参数设置!$C$17*参数设置!$C$21,0)
A13: 10 | B13: =IFERROR(原料BOM!B13,"") | C13: =IFERROR(原料BOM!C13,"") | D13: =IFERROR(原料BOM!D13,"") | E13: =IFERROR(SUMPRODUCT(原料BOM!E13:P13,产品SKU!$G$3:产品SKU!$G$14),0) | H13: =参数设置!$C$7 | M13: =IFERROR(MAX(原料仓计算!E13*原料仓计算!F13,IF(原料仓计算!G13="",0,原料仓计算!G13))*原料仓计算!H13+IF(原料仓计算!I13="",0,原料仓计算!I13)+IF(原料仓计算!J13="",0,原料仓计算!J13)+IF(原料仓计算!K13="",0,原料仓计算!K13)+IF(原料仓计算!L13="",0,原料仓计算!L13),0) | O13: =IFERROR(CEILING(原料仓计算!M13/IF(原料仓计算!N13=0,1,原料仓计算!N13),1),0) | P13: =IFERROR(原料仓计算!O13*参数设置!$C$13/MAX(参数设置!$C$14,1)/参数设置!$C$17*参数设置!$C$21,0)
A14: 11 | B14: =IFERROR(原料BOM!B14,"") | C14: =IFERROR(原料BOM!C14,"") | D14: =IFERROR(原料BOM!D14,"") | E14: =IFERROR(SUMPRODUCT(原料BOM!E14:P14,产品SKU!$G$3:产品SKU!$G$14),0) | H14: =参数设置!$C$7 | M14: =IFERROR(MAX(原料仓计算!E14*原料仓计算!F14,IF(原料仓计算!G14="",0,原料仓计算!G14))*原料仓计算!H14+IF(原料仓计算!I14="",0,原料仓计算!I14)+IF(原料仓计算!J14="",0,原料仓计算!J14)+IF(原料仓计算!K14="",0,原料仓计算!K14)+IF(原料仓计算!L14="",0,原料仓计算!L14),0) | O14: =IFERROR(CEILING(原料仓计算!M14/IF(原料仓计算!N14=0,1,原料仓计算!N14),1),0) | P14: =IFERROR(原料仓计算!O14*参数设置!$C$13/MAX(参数设置!$C$14,1)/参数设置!$C$17*参数设置!$C$21,0)
A15: 12 | B15: =IFERROR(原料BOM!B15,"") | C15: =IFERROR(原料BOM!C15,"") | D15: =IFERROR(原料BOM!D15,"") | E15: =IFERROR(SUMPRODUCT(原料BOM!E15:P15,产品SKU!$G$3:产品SKU!$G$14),0) | H15: =参数设置!$C$7 | M15: =IFERROR(MAX(原料仓计算!E15*原料仓计算!F15,IF(原料仓计算!G15="",0,原料仓计算!G15))*原料仓计算!H15+IF(原料仓计算!I15="",0,原料仓计算!I15)+IF(原料仓计算!J15="",0,原料仓计算!J15)+IF(原料仓计算!K15="",0,原料仓计算!K15)+IF(原料仓计算!L15="",0,原料仓计算!L15),0) | O15: =IFERROR(CEILING(原料仓计算!M15/IF(原料仓计算!N15=0,1,原料仓计算!N15),1),0) | P15: =IFERROR(原料仓计算!O15*参数设置!$C$13/MAX(参数设置!$C$14,1)/参数设置!$C$17*参数设置!$C$21,0)
A16: 13 | B16: =IFERROR(原料BOM!B16,"") | C16: =IFERROR(原料BOM!C16,"") | D16: =IFERROR(原料BOM!D16,"") | E16: =IFERROR(SUMPRODUCT(原料BOM!E16:P16,产品SKU!$G$3:产品SKU!$G$14),0) | H16: =参数设置!$C$7 | M16: =IFERROR(MAX(原料仓计算!E16*原料仓计算!F16,IF(原料仓计算!G16="",0,原料仓计算!G16))*原料仓计算!H16+IF(原料仓计算!I16="",0,原料仓计算!I16)+IF(原料仓计算!J16="",0,原料仓计算!J16)+IF(原料仓计算!K16="",0,原料仓计算!K16)+IF(原料仓计算!L16="",0,原料仓计算!L16),0) | O16: =IFERROR(CEILING(原料仓计算!M16/IF(原料仓计算!N16=0,1,原料仓计算!N16),1),0) | P16: =IFERROR(原料仓计算!O16*参数设置!$C$13/MAX(参数设置!$C$14,1)/参数设置!$C$17*参数设置!$C$21,0)
A17: 14 | B17: =IFERROR(原料BOM!B17,"") | C17: =IFERROR(原料BOM!C17,"") | D17: =IFERROR(原料BOM!D17,"") | E17: =IFERROR(SUMPRODUCT(原料BOM!E17:P17,产品SKU!$G$3:产品SKU!$G$14),0) | H17: =参数设置!$C$7 | M17: =IFERROR(MAX(原料仓计算!E17*原料仓计算!F17,IF(原料仓计算!G17="",0,原料仓计算!G17))*原料仓计算!H17+IF(原料仓计算!I17="",0,原料仓计算!I17)+IF(原料仓计算!J17="",0,原料仓计算!J17)+IF(原料仓计算!K17="",0,原料仓计算!K17)+IF(原料仓计算!L17="",0,原料仓计算!L17),0) | O17: =IFERROR(CEILING(原料仓计算!M17/IF(原料仓计算!N17=0,1,原料仓计算!N17),1),0) | P17: =IFERROR(原料仓计算!O17*参数设置!$C$13/MAX(参数设置!$C$14,1)/参数设置!$C$17*参数设置!$C$21,0)
A18: 15 | B18: =IFERROR(原料BOM!B18,"") | C18: =IFERROR(原料BOM!C18,"") | D18: =IFERROR(原料BOM!D18,"") | E18: =IFERROR(SUMPRODUCT(原料BOM!E18:P18,产品SKU!$G$3:产品SKU!$G$14),0) | H18: =参数设置!$C$7 | M18: =IFERROR(MAX(原料仓计算!E18*原料仓计算!F18,IF(原料仓计算!G18="",0,原料仓计算!G18))*原料仓计算!H18+IF(原料仓计算!I18="",0,原料仓计算!I18)+IF(原料仓计算!J18="",0,原料仓计算!J18)+IF(原料仓计算!K18="",0,原料仓计算!K18)+IF(原料仓计算!L18="",0,原料仓计算!L18),0) | O18: =IFERROR(CEILING(原料仓计算!M18/IF(原料仓计算!N18=0,1,原料仓计算!N18),1),0) | P18: =IFERROR(原料仓计算!O18*参数设置!$C$13/MAX(参数设置!$C$14,1)/参数设置!$C$17*参数设置!$C$21,0)
A19: 合计 | M19: =SUM(M4:M18) | O19: =SUM(O4:O18) | P19: =SUM(P4:P18)

Sheet 过程品仓计算
A1: 过程品仓计算 — 工序WIP设计库存量
A2: 公式：设计WIP = MAX(下游小时消耗×缓冲小时数, 批量×最大等待批次数) + 待检库存 + 尾批库存 + 不良品/返工/隔离库存
A3: 行号 | B3: 工序位置 | C3: 产品SKU | D3: 单位 | E3: 日产量 (件/天) [自动] | F3: 小时产量 [自动] | G3: 缓冲小时数 | H3: 按缓冲时间 计算WIP [自动] | I3: 批量大小 (件) | J3: 最大等待 批次数 | K3: 按批量计算 WIP [自动] | L3: 设计基础WIP =MAX(...) [自动] | M3: 待检等待 库存 | N3: 尾批库存 | O3: 不良/返工/ 隔离库存 | P3: 设计WIP 合计 [自动] | Q3: 估算占地 面积(m²) [自动]
A4: 【工序1后暂存】
A5: 1 | B5: 工序1后暂存 | C5: =IFERROR(产品SKU!B3,"") | D5: =IFERROR(产品SKU!D3,"") | E5: =IFERROR(产品SKU!G3,0) | F5: =IFERROR(过程品仓计算!E5/参数设置!$C$5,0) | G5: =IFERROR(产品SKU!O3,0) | H5: =IFERROR(过程品仓计算!F5*过程品仓计算!G5,0) | J5: 2 | K5: =IFERROR(IF(过程品仓计算!I5="",0,过程品仓计算!I5)*IF(过程品仓计算!J5="",0,过程品仓计算!J5),0) | L5: =IFERROR(MAX(过程品仓计算!H5,过程品仓计算!K5),0) | P5: =IFERROR(过程品仓计算!L5+IF(过程品仓计算!M5="",0,过程品仓计算!M5)+IF(过程品仓计算!N5="",0,过程品仓计算!N5)+IF(过程品仓计算!O5="",0,过程品仓计算!O5),0) | Q5: =IFERROR(CEILING(过程品仓计算!P5/MAX(产品SKU!M3,1),1)*参数设置!$C$13/MAX(参数设置!$C$14,1)/参数设置!$C$18*参数设置!$C$21,0)
A6: 2 | B6: 工序1后暂存 | C6: =IFERROR(产品SKU!B4,"") | D6: =IFERROR(产品SKU!D4,"") | E6: =IFERROR(产品SKU!G4,0) | F6: =IFERROR(过程品仓计算!E6/参数设置!$C$5,0) | G6: =IFERROR(产品SKU!O4,0) | H6: =IFERROR(过程品仓计算!F6*过程品仓计算!G6,0) | J6: 2 | K6: =IFERROR(IF(过程品仓计算!I6="",0,过程品仓计算!I6)*IF(过程品仓计算!J6="",0,过程品仓计算!J6),0) | L6: =IFERROR(MAX(过程品仓计算!H6,过程品仓计算!K6),0) | P6: =IFERROR(过程品仓计算!L6+IF(过程品仓计算!M6="",0,过程品仓计算!M6)+IF(过程品仓计算!N6="",0,过程品仓计算!N6)+IF(过程品仓计算!O6="",0,过程品仓计算!O6),0) | Q6: =IFERROR(CEILING(过程品仓计算!P6/MAX(产品SKU!M4,1),1)*参数设置!$C$13/MAX(参数设置!$C$14,1)/参数设置!$C$18*参数设置!$C$21,0)
A7: 3 | B7: 工序1后暂存 | C7: =IFERROR(产品SKU!B5,"") | D7: =IFERROR(产品SKU!D5,"") | E7: =IFERROR(产品SKU!G5,0) | F7: =IFERROR(过程品仓计算!E7/参数设置!$C$5,0) | G7: =IFERROR(产品SKU!O5,0) | H7: =IFERROR(过程品仓计算!F7*过程品仓计算!G7,0) | J7: 2 | K7: =IFERROR(IF(过程品仓计算!I7="",0,过程品仓计算!I7)*IF(过程品仓计算!J7="",0,过程品仓计算!J7),0) | L7: =IFERROR(MAX(过程品仓计算!H7,过程品仓计算!K7),0) | P7: =IFERROR(过程品仓计算!L7+IF(过程品仓计算!M7="",0,过程品仓计算!M7)+IF(过程品仓计算!N7="",0,过程品仓计算!N7)+IF(过程品仓计算!O7="",0,过程品仓计算!O7),0) | Q7: =IFERROR(CEILING(过程品仓计算!P7/MAX(产品SKU!M5,1),1)*参数设置!$C$13/MAX(参数设置!$C$14,1)/参数设置!$C$18*参数设置!$C$21,0)
A8: 4 | B8: 工序1后暂存 | C8: =IFERROR(产品SKU!B6,"") | D8: =IFERROR(产品SKU!D6,"") | E8: =IFERROR(产品SKU!G6,0) | F8: =IFERROR(过程品仓计算!E8/参数设置!$C$5,0) | G8: =IFERROR(产品SKU!O6,0) | H8: =IFERROR(过程品仓计算!F8*过程品仓计算!G8,0) | J8: 2 | K8: =IFERROR(IF(过程品仓计算!I8="",0,过程品仓计算!I8)*IF(过程品仓计算!J8="",0,过程品仓计算!J8),0) | L8: =IFERROR(MAX(过程品仓计算!H8,过程品仓计算!K8),0) | P8: =IFERROR(过程品仓计算!L8+IF(过程品仓计算!M8="",0,过程品仓计算!M8)+IF(过程品仓计算!N8="",0,过程品仓计算!N8)+IF(过程品仓计算!O8="",0,过程品仓计算!O8),0) | Q8: =IFERROR(CEILING(过程品仓计算!P8/MAX(产品SKU!M6,1),1)*参数设置!$C$13/MAX(参数设置!$C$14,1)/参数设置!$C$18*参数设置!$C$21,0)
A9: 5 | B9: 工序1后暂存 | C9: =IFERROR(产品SKU!B7,"") | D9: =IFERROR(产品SKU!D7,"") | E9: =IFERROR(产品SKU!G7,0) | F9: =IFERROR(过程品仓计算!E9/参数设置!$C$5,0) | G9: =IFERROR(产品SKU!O7,0) | H9: =IFERROR(过程品仓计算!F9*过程品仓计算!G9,0) | J9: 2 | K9: =IFERROR(IF(过程品仓计算!I9="",0,过程品仓计算!I9)*IF(过程品仓计算!J9="",0,过程品仓计算!J9),0) | L9: =IFERROR(MAX(过程品仓计算!H9,过程品仓计算!K9),0) | P9: =IFERROR(过程品仓计算!L9+IF(过程品仓计算!M9="",0,过程品仓计算!M9)+IF(过程品仓计算!N9="",0,过程品仓计算!N9)+IF(过程品仓计算!O9="",0,过程品仓计算!O9),0) | Q9: =IFERROR(CEILING(过程品仓计算!P9/MAX(产品SKU!M7,1),1)*参数设置!$C$13/MAX(参数设置!$C$14,1)/参数设置!$C$18*参数设置!$C$21,0)
A10: 6 | B10: 工序1后暂存 | C10: =IFERROR(产品SKU!B8,"") | D10: =IFERROR(产品SKU!D8,"") | E10: =IFERROR(产品SKU!G8,0) | F10: =IFERROR(过程品仓计算!E10/参数设置!$C$5,0) | G10: =IFERROR(产品SKU!O8,0) | H10: =IFERROR(过程品仓计算!F10*过程品仓计算!G10,0) | J10: 2 | K10: =IFERROR(IF(过程品仓计算!I10="",0,过程品仓计算!I10)*IF(过程品仓计算!J10="",0,过程品仓计算!J10),0) | L10: =IFERROR(MAX(过程品仓计算!H10,过程品仓计算!K10),0) | P10: =IFERROR(过程品仓计算!L10+IF(过程品仓计算!M10="",0,过程品仓计算!M10)+IF(过程品仓计算!N10="",0,过程品仓计算!N10)+IF(过程品仓计算!O10="",0,过程品仓计算!O10),0) | Q10: =IFERROR(CEILING(过程品仓计算!P10/MAX(产品SKU!M8,1),1)*参数设置!$C$13/MAX(参数设置!$C$14,1)/参数设置!$C$18*参数设置!$C$21,0)
A11: 7 | B11: 工序1后暂存 | C11: =IFERROR(产品SKU!B9,"") | D11: =IFERROR(产品SKU!D9,"") | E11: =IFERROR(产品SKU!G9,0) | F11: =IFERROR(过程品仓计算!E11/参数设置!$C$5,0) | G11: =IFERROR(产品SKU!O9,0) | H11: =IFERROR(过程品仓计算!F11*过程品仓计算!G11,0) | J11: 2 | K11: =IFERROR(IF(过程品仓计算!I11="",0,过程品仓计算!I11)*IF(过程品仓计算!J11="",0,过程品仓计算!J11),0) | L11: =IFERROR(MAX(过程品仓计算!H11,过程品仓计算!K11),0) | P11: =IFERROR(过程品仓计算!L11+IF(过程品仓计算!M11="",0,过程品仓计算!M11)+IF(过程品仓计算!N11="",0,过程品仓计算!N11)+IF(过程品仓计算!O11="",0,过程品仓计算!O11),0) | Q11: =IFERROR(CEILING(过程品仓计算!P11/MAX(产品SKU!M9,1),1)*参数设置!$C$13/MAX(参数设置!$C$14,1)/参数设置!$C$18*参数设置!$C$21,0)
A12: 8 | B12: 工序1后暂存 | C12: =IFERROR(产品SKU!B10,"") | D12: =IFERROR(产品SKU!D10,"") | E12: =IFERROR(产品SKU!G10,0) | F12: =IFERROR(过程品仓计算!E12/参数设置!$C$5,0) | G12: =IFERROR(产品SKU!O10,0) | H12: =IFERROR(过程品仓计算!F12*过程品仓计算!G12,0) | J12: 2 | K12: =IFERROR(IF(过程品仓计算!I12="",0,过程品仓计算!I12)*IF(过程品仓计算!J12="",0,过程品仓计算!J12),0) | L12: =IFERROR(MAX(过程品仓计算!H12,过程品仓计算!K12),0) | P12: =IFERROR(过程品仓计算!L12+IF(过程品仓计算!M12="",0,过程品仓计算!M12)+IF(过程品仓计算!N12="",0,过程品仓计算!N12)+IF(过程品仓计算!O12="",0,过程品仓计算!O12),0) | Q12: =IFERROR(CEILING(过程品仓计算!P12/MAX(产品SKU!M10,1),1)*参数设置!$C$13/MAX(参数设置!$C$14,1)/参数设置!$C$18*参数设置!$C$21,0)
A13: 9 | B13: 工序1后暂存 | C13: =IFERROR(产品SKU!B11,"") | D13: =IFERROR(产品SKU!D11,"") | E13: =IFERROR(产品SKU!G11,0) | F13: =IFERROR(过程品仓计算!E13/参数设置!$C$5,0) | G13: =IFERROR(产品SKU!O11,0) | H13: =IFERROR(过程品仓计算!F13*过程品仓计算!G13,0) | J13: 2 | K13: =IFERROR(IF(过程品仓计算!I13="",0,过程品仓计算!I13)*IF(过程品仓计算!J13="",0,过程品仓计算!J13),0) | L13: =IFERROR(MAX(过程品仓计算!H13,过程品仓计算!K13),0) | P13: =IFERROR(过程品仓计算!L13+IF(过程品仓计算!M13="",0,过程品仓计算!M13)+IF(过程品仓计算!N13="",0,过程品仓计算!N13)+IF(过程品仓计算!O13="",0,过程品仓计算!O13),0) | Q13: =IFERROR(CEILING(过程品仓计算!P13/MAX(产品SKU!M11,1),1)*参数设置!$C$13/MAX(参数设置!$C$14,1)/参数设置!$C$18*参数设置!$C$21,0)
A14: 10 | B14: 工序1后暂存 | C14: =IFERROR(产品SKU!B12,"") | D14: =IFERROR(产品SKU!D12,"") | E14: =IFERROR(产品SKU!G12,0) | F14: =IFERROR(过程品仓计算!E14/参数设置!$C$5,0) | G14: =IFERROR(产品SKU!O12,0) | H14: =IFERROR(过程品仓计算!F14*过程品仓计算!G14,0) | J14: 2 | K14: =IFERROR(IF(过程品仓计算!I14="",0,过程品仓计算!I14)*IF(过程品仓计算!J14="",0,过程品仓计算!J14),0) | L14: =IFERROR(MAX(过程品仓计算!H14,过程品仓计算!K14),0) | P14: =IFERROR(过程品仓计算!L14+IF(过程品仓计算!M14="",0,过程品仓计算!M14)+IF(过程品仓计算!N14="",0,过程品仓计算!N14)+IF(过程品仓计算!O14="",0,过程品仓计算!O14),0) | Q14: =IFERROR(CEILING(过程品仓计算!P14/MAX(产品SKU!M12,1),1)*参数设置!$C$13/MAX(参数设置!$C$14,1)/参数设置!$C$18*参数设置!$C$21,0)
A15: 11 | B15: 工序1后暂存 | C15: =IFERROR(产品SKU!B13,"") | D15: =IFERROR(产品SKU!D13,"") | E15: =IFERROR(产品SKU!G13,0) | F15: =IFERROR(过程品仓计算!E15/参数设置!$C$5,0) | G15: =IFERROR(产品SKU!O13,0) | H15: =IFERROR(过程品仓计算!F15*过程品仓计算!G15,0) | J15: 2 | K15: =IFERROR(IF(过程品仓计算!I15="",0,过程品仓计算!I15)*IF(过程品仓计算!J15="",0,过程品仓计算!J15),0) | L15: =IFERROR(MAX(过程品仓计算!H15,过程品仓计算!K15),0) | P15: =IFERROR(过程品仓计算!L15+IF(过程品仓计算!M15="",0,过程品仓计算!M15)+IF(过程品仓计算!N15="",0,过程品仓计算!N15)+IF(过程品仓计算!O15="",0,过程品仓计算!O15),0) | Q15: =IFERROR(CEILING(过程品仓计算!P15/MAX(产品SKU!M13,1),1)*参数设置!$C$13/MAX(参数设置!$C$14,1)/参数设置!$C$18*参数设置!$C$21,0)
A16: 12 | B16: 工序1后暂存 | C16: =IFERROR(产品SKU!B14,"") | D16: =IFERROR(产品SKU!D14,"") | E16: =IFERROR(产品SKU!G14,0) | F16: =IFERROR(过程品仓计算!E16/参数设置!$C$5,0) | G16: =IFERROR(产品SKU!O14,0) | H16: =IFERROR(过程品仓计算!F16*过程品仓计算!G16,0) | J16: 2 | K16: =IFERROR(IF(过程品仓计算!I16="",0,过程品仓计算!I16)*IF(过程品仓计算!J16="",0,过程品仓计算!J16),0) | L16: =IFERROR(MAX(过程品仓计算!H16,过程品仓计算!K16),0) | P16: =IFERROR(过程品仓计算!L16+IF(过程品仓计算!M16="",0,过程品仓计算!M16)+IF(过程品仓计算!N16="",0,过程品仓计算!N16)+IF(过程品仓计算!O16="",0,过程品仓计算!O16),0) | Q16: =IFERROR(CEILING(过程品仓计算!P16/MAX(产品SKU!M14,1),1)*参数设置!$C$13/MAX(参数设置!$C$14,1)/参数设置!$C$18*参数设置!$C$21,0)
A17: 工序1后暂存 小计 | P17: =SUM(P5:P16) | Q17: =SUM(Q5:Q16)
A18: 【工序2后暂存】
A19: 1 | B19: 工序2后暂存 | C19: =IFERROR(产品SKU!B3,"") | D19: =IFERROR(产品SKU!D3,"") | E19: =IFERROR(产品SKU!G3,0) | F19: =IFERROR(过程品仓计算!E19/参数设置!$C$5,0) | G19: =IFERROR(产品SKU!P3,0) | H19: =IFERROR(过程品仓计算!F19*过程品仓计算!G19,0) | J19: 2 | K19: =IFERROR(IF(过程品仓计算!I19="",0,过程品仓计算!I19)*IF(过程品仓计算!J19="",0,过程品仓计算!J19),0) | L19: =IFERROR(MAX(过程品仓计算!H19,过程品仓计算!K19),0) | P19: =IFERROR(过程品仓计算!L19+IF(过程品仓计算!M19="",0,过程品仓计算!M19)+IF(过程品仓计算!N19="",0,过程品仓计算!N19)+IF(过程品仓计算!O19="",0,过程品仓计算!O19),0) | Q19: =IFERROR(CEILING(过程品仓计算!P19/MAX(产品SKU!M3,1),1)*参数设置!$C$13/MAX(参数设置!$C$14,1)/参数设置!$C$18*参数设置!$C$21,0)
A20: 2 | B20: 工序2后暂存 | C20: =IFERROR(产品SKU!B4,"") | D20: =IFERROR(产品SKU!D4,"") | E20: =IFERROR(产品SKU!G4,0) | F20: =IFERROR(过程品仓计算!E20/参数设置!$C$5,0) | G20: =IFERROR(产品SKU!P4,0) | H20: =IFERROR(过程品仓计算!F20*过程品仓计算!G20,0) | J20: 2 | K20: =IFERROR(IF(过程品仓计算!I20="",0,过程品仓计算!I20)*IF(过程品仓计算!J20="",0,过程品仓计算!J20),0) | L20: =IFERROR(MAX(过程品仓计算!H20,过程品仓计算!K20),0) | P20: =IFERROR(过程品仓计算!L20+IF(过程品仓计算!M20="",0,过程品仓计算!M20)+IF(过程品仓计算!N20="",0,过程品仓计算!N20)+IF(过程品仓计算!O20="",0,过程品仓计算!O20),0) | Q20: =IFERROR(CEILING(过程品仓计算!P20/MAX(产品SKU!M4,1),1)*参数设置!$C$13/MAX(参数设置!$C$14,1)/参数设置!$C$18*参数设置!$C$21,0)
A21: 3 | B21: 工序2后暂存 | C21: =IFERROR(产品SKU!B5,"") | D21: =IFERROR(产品SKU!D5,"") | E21: =IFERROR(产品SKU!G5,0) | F21: =IFERROR(过程品仓计算!E21/参数设置!$C$5,0) | G21: =IFERROR(产品SKU!P5,0) | H21: =IFERROR(过程品仓计算!F21*过程品仓计算!G21,0) | J21: 2 | K21: =IFERROR(IF(过程品仓计算!I21="",0,过程品仓计算!I21)*IF(过程品仓计算!J21="",0,过程品仓计算!J21),0) | L21: =IFERROR(MAX(过程品仓计算!H21,过程品仓计算!K21),0) | P21: =IFERROR(过程品仓计算!L21+IF(过程品仓计算!M21="",0,过程品仓计算!M21)+IF(过程品仓计算!N21="",0,过程品仓计算!N21)+IF(过程品仓计算!O21="",0,过程品仓计算!O21),0) | Q21: =IFERROR(CEILING(过程品仓计算!P21/MAX(产品SKU!M5,1),1)*参数设置!$C$13/MAX(参数设置!$C$14,1)/参数设置!$C$18*参数设置!$C$21,0)
A22: 4 | B22: 工序2后暂存 | C22: =IFERROR(产品SKU!B6,"") | D22: =IFERROR(产品SKU!D6,"") | E22: =IFERROR(产品SKU!G6,0) | F22: =IFERROR(过程品仓计算!E22/参数设置!$C$5,0) | G22: =IFERROR(产品SKU!P6,0) | H22: =IFERROR(过程品仓计算!F22*过程品仓计算!G22,0) | J22: 2 | K22: =IFERROR(IF(过程品仓计算!I22="",0,过程品仓计算!I22)*IF(过程品仓计算!J22="",0,过程品仓计算!J22),0) | L22: =IFERROR(MAX(过程品仓计算!H22,过程品仓计算!K22),0) | P22: =IFERROR(过程品仓计算!L22+IF(过程品仓计算!M22="",0,过程品仓计算!M22)+IF(过程品仓计算!N22="",0,过程品仓计算!N22)+IF(过程品仓计算!O22="",0,过程品仓计算!O22),0) | Q22: =IFERROR(CEILING(过程品仓计算!P22/MAX(产品SKU!M6,1),1)*参数设置!$C$13/MAX(参数设置!$C$14,1)/参数设置!$C$18*参数设置!$C$21,0)
A23: 5 | B23: 工序2后暂存 | C23: =IFERROR(产品SKU!B7,"") | D23: =IFERROR(产品SKU!D7,"") | E23: =IFERROR(产品SKU!G7,0) | F23: =IFERROR(过程品仓计算!E23/参数设置!$C$5,0) | G23: =IFERROR(产品SKU!P7,0) | H23: =IFERROR(过程品仓计算!F23*过程品仓计算!G23,0) | J23: 2 | K23: =IFERROR(IF(过程品仓计算!I23="",0,过程品仓计算!I23)*IF(过程品仓计算!J23="",0,过程品仓计算!J23),0) | L23: =IFERROR(MAX(过程品仓计算!H23,过程品仓计算!K23),0) | P23: =IFERROR(过程品仓计算!L23+IF(过程品仓计算!M23="",0,过程品仓计算!M23)+IF(过程品仓计算!N23="",0,过程品仓计算!N23)+IF(过程品仓计算!O23="",0,过程品仓计算!O23),0) | Q23: =IFERROR(CEILING(过程品仓计算!P23/MAX(产品SKU!M7,1),1)*参数设置!$C$13/MAX(参数设置!$C$14,1)/参数设置!$C$18*参数设置!$C$21,0)
A24: 6 | B24: 工序2后暂存 | C24: =IFERROR(产品SKU!B8,"") | D24: =IFERROR(产品SKU!D8,"") | E24: =IFERROR(产品SKU!G8,0) | F24: =IFERROR(过程品仓计算!E24/参数设置!$C$5,0) | G24: =IFERROR(产品SKU!P8,0) | H24: =IFERROR(过程品仓计算!F24*过程品仓计算!G24,0) | J24: 2 | K24: =IFERROR(IF(过程品仓计算!I24="",0,过程品仓计算!I24)*IF(过程品仓计算!J24="",0,过程品仓计算!J24),0) | L24: =IFERROR(MAX(过程品仓计算!H24,过程品仓计算!K24),0) | P24: =IFERROR(过程品仓计算!L24+IF(过程品仓计算!M24="",0,过程品仓计算!M24)+IF(过程品仓计算!N24="",0,过程品仓计算!N24)+IF(过程品仓计算!O24="",0,过程品仓计算!O24),0) | Q24: =IFERROR(CEILING(过程品仓计算!P24/MAX(产品SKU!M8,1),1)*参数设置!$C$13/MAX(参数设置!$C$14,1)/参数设置!$C$18*参数设置!$C$21,0)
A25: 7 | B25: 工序2后暂存 | C25: =IFERROR(产品SKU!B9,"") | D25: =IFERROR(产品SKU!D9,"") | E25: =IFERROR(产品SKU!G9,0) | F25: =IFERROR(过程品仓计算!E25/参数设置!$C$5,0) | G25: =IFERROR(产品SKU!P9,0) | H25: =IFERROR(过程品仓计算!F25*过程品仓计算!G25,0) | J25: 2 | K25: =IFERROR(IF(过程品仓计算!I25="",0,过程品仓计算!I25)*IF(过程品仓计算!J25="",0,过程品仓计算!J25),0) | L25: =IFERROR(MAX(过程品仓计算!H25,过程品仓计算!K25),0) | P25: =IFERROR(过程品仓计算!L25+IF(过程品仓计算!M25="",0,过程品仓计算!M25)+IF(过程品仓计算!N25="",0,过程品仓计算!N25)+IF(过程品仓计算!O25="",0,过程品仓计算!O25),0) | Q25: =IFERROR(CEILING(过程品仓计算!P25/MAX(产品SKU!M9,1),1)*参数设置!$C$13/MAX(参数设置!$C$14,1)/参数设置!$C$18*参数设置!$C$21,0)
A26: 8 | B26: 工序2后暂存 | C26: =IFERROR(产品SKU!B10,"") | D26: =IFERROR(产品SKU!D10,"") | E26: =IFERROR(产品SKU!G10,0) | F26: =IFERROR(过程品仓计算!E26/参数设置!$C$5,0) | G26: =IFERROR(产品SKU!P10,0) | H26: =IFERROR(过程品仓计算!F26*过程品仓计算!G26,0) | J26: 2 | K26: =IFERROR(IF(过程品仓计算!I26="",0,过程品仓计算!I26)*IF(过程品仓计算!J26="",0,过程品仓计算!J26),0) | L26: =IFERROR(MAX(过程品仓计算!H26,过程品仓计算!K26),0) | P26: =IFERROR(过程品仓计算!L26+IF(过程品仓计算!M26="",0,过程品仓计算!M26)+IF(过程品仓计算!N26="",0,过程品仓计算!N26)+IF(过程品仓计算!O26="",0,过程品仓计算!O26),0) | Q26: =IFERROR(CEILING(过程品仓计算!P26/MAX(产品SKU!M10,1),1)*参数设置!$C$13/MAX(参数设置!$C$14,1)/参数设置!$C$18*参数设置!$C$21,0)
A27: 9 | B27: 工序2后暂存 | C27: =IFERROR(产品SKU!B11,"") | D27: =IFERROR(产品SKU!D11,"") | E27: =IFERROR(产品SKU!G11,0) | F27: =IFERROR(过程品仓计算!E27/参数设置!$C$5,0) | G27: =IFERROR(产品SKU!P11,0) | H27: =IFERROR(过程品仓计算!F27*过程品仓计算!G27,0) | J27: 2 | K27: =IFERROR(IF(过程品仓计算!I27="",0,过程品仓计算!I27)*IF(过程品仓计算!J27="",0,过程品仓计算!J27),0) | L27: =IFERROR(MAX(过程品仓计算!H27,过程品仓计算!K27),0) | P27: =IFERROR(过程品仓计算!L27+IF(过程品仓计算!M27="",0,过程品仓计算!M27)+IF(过程品仓计算!N27="",0,过程品仓计算!N27)+IF(过程品仓计算!O27="",0,过程品仓计算!O27),0) | Q27: =IFERROR(CEILING(过程品仓计算!P27/MAX(产品SKU!M11,1),1)*参数设置!$C$13/MAX(参数设置!$C$14,1)/参数设置!$C$18*参数设置!$C$21,0)
A28: 10 | B28: 工序2后暂存 | C28: =IFERROR(产品SKU!B12,"") | D28: =IFERROR(产品SKU!D12,"") | E28: =IFERROR(产品SKU!G12,0) | F28: =IFERROR(过程品仓计算!E28/参数设置!$C$5,0) | G28: =IFERROR(产品SKU!P12,0) | H28: =IFERROR(过程品仓计算!F28*过程品仓计算!G28,0) | J28: 2 | K28: =IFERROR(IF(过程品仓计算!I28="",0,过程品仓计算!I28)*IF(过程品仓计算!J28="",0,过程品仓计算!J28),0) | L28: =IFERROR(MAX(过程品仓计算!H28,过程品仓计算!K28),0) | P28: =IFERROR(过程品仓计算!L28+IF(过程品仓计算!M28="",0,过程品仓计算!M28)+IF(过程品仓计算!N28="",0,过程品仓计算!N28)+IF(过程品仓计算!O28="",0,过程品仓计算!O28),0) | Q28: =IFERROR(CEILING(过程品仓计算!P28/MAX(产品SKU!M12,1),1)*参数设置!$C$13/MAX(参数设置!$C$14,1)/参数设置!$C$18*参数设置!$C$21,0)
A29: 11 | B29: 工序2后暂存 | C29: =IFERROR(产品SKU!B13,"") | D29: =IFERROR(产品SKU!D13,"") | E29: =IFERROR(产品SKU!G13,0) | F29: =IFERROR(过程品仓计算!E29/参数设置!$C$5,0) | G29: =IFERROR(产品SKU!P13,0) | H29: =IFERROR(过程品仓计算!F29*过程品仓计算!G29,0) | J29: 2 | K29: =IFERROR(IF(过程品仓计算!I29="",0,过程品仓计算!I29)*IF(过程品仓计算!J29="",0,过程品仓计算!J29),0) | L29: =IFERROR(MAX(过程品仓计算!H29,过程品仓计算!K29),0) | P29: =IFERROR(过程品仓计算!L29+IF(过程品仓计算!M29="",0,过程品仓计算!M29)+IF(过程品仓计算!N29="",0,过程品仓计算!N29)+IF(过程品仓计算!O29="",0,过程品仓计算!O29),0) | Q29: =IFERROR(CEILING(过程品仓计算!P29/MAX(产品SKU!M13,1),1)*参数设置!$C$13/MAX(参数设置!$C$14,1)/参数设置!$C$18*参数设置!$C$21,0)
A30: 12 | B30: 工序2后暂存 | C30: =IFERROR(产品SKU!B14,"") | D30: =IFERROR(产品SKU!D14,"") | E30: =IFERROR(产品SKU!G14,0) | F30: =IFERROR(过程品仓计算!E30/参数设置!$C$5,0) | G30: =IFERROR(产品SKU!P14,0) | H30: =IFERROR(过程品仓计算!F30*过程品仓计算!G30,0) | J30: 2 | K30: =IFERROR(IF(过程品仓计算!I30="",0,过程品仓计算!I30)*IF(过程品仓计算!J30="",0,过程品仓计算!J30),0) | L30: =IFERROR(MAX(过程品仓计算!H30,过程品仓计算!K30),0) | P30: =IFERROR(过程品仓计算!L30+IF(过程品仓计算!M30="",0,过程品仓计算!M30)+IF(过程品仓计算!N30="",0,过程品仓计算!N30)+IF(过程品仓计算!O30="",0,过程品仓计算!O30),0) | Q30: =IFERROR(CEILING(过程品仓计算!P30/MAX(产品SKU!M14,1),1)*参数设置!$C$13/MAX(参数设置!$C$14,1)/参数设置!$C$18*参数设置!$C$21,0)
A31: 工序2后暂存 小计 | P31: =SUM(P19:P30) | Q31: =SUM(Q19:Q30)
A32: 【工序3后暂存（成品前）】
A33: 1 | B33: 工序3后暂存（成品前） | C33: =IFERROR(产品SKU!B3,"") | D33: =IFERROR(产品SKU!D3,"") | E33: =IFERROR(产品SKU!G3,0) | F33: =IFERROR(过程品仓计算!E33/参数设置!$C$5,0) | G33: =IFERROR(产品SKU!Q3,0) | H33: =IFERROR(过程品仓计算!F33*过程品仓计算!G33,0) | J33: 2 | K33: =IFERROR(IF(过程品仓计算!I33="",0,过程品仓计算!I33)*IF(过程品仓计算!J33="",0,过程品仓计算!J33),0) | L33: =IFERROR(MAX(过程品仓计算!H33,过程品仓计算!K33),0) | P33: =IFERROR(过程品仓计算!L33+IF(过程品仓计算!M33="",0,过程品仓计算!M33)+IF(过程品仓计算!N33="",0,过程品仓计算!N33)+IF(过程品仓计算!O33="",0,过程品仓计算!O33),0) | Q33: =IFERROR(CEILING(过程品仓计算!P33/MAX(产品SKU!M3,1),1)*参数设置!$C$13/MAX(参数设置!$C$14,1)/参数设置!$C$18*参数设置!$C$21,0)
A34: 2 | B34: 工序3后暂存（成品前） | C34: =IFERROR(产品SKU!B4,"") | D34: =IFERROR(产品SKU!D4,"") | E34: =IFERROR(产品SKU!G4,0) | F34: =IFERROR(过程品仓计算!E34/参数设置!$C$5,0) | G34: =IFERROR(产品SKU!Q4,0) | H34: =IFERROR(过程品仓计算!F34*过程品仓计算!G34,0) | J34: 2 | K34: =IFERROR(IF(过程品仓计算!I34="",0,过程品仓计算!I34)*IF(过程品仓计算!J34="",0,过程品仓计算!J34),0) | L34: =IFERROR(MAX(过程品仓计算!H34,过程品仓计算!K34),0) | P34: =IFERROR(过程品仓计算!L34+IF(过程品仓计算!M34="",0,过程品仓计算!M34)+IF(过程品仓计算!N34="",0,过程品仓计算!N34)+IF(过程品仓计算!O34="",0,过程品仓计算!O34),0) | Q34: =IFERROR(CEILING(过程品仓计算!P34/MAX(产品SKU!M4,1),1)*参数设置!$C$13/MAX(参数设置!$C$14,1)/参数设置!$C$18*参数设置!$C$21,0)
A35: 3 | B35: 工序3后暂存（成品前） | C35: =IFERROR(产品SKU!B5,"") | D35: =IFERROR(产品SKU!D5,"") | E35: =IFERROR(产品SKU!G5,0) | F35: =IFERROR(过程品仓计算!E35/参数设置!$C$5,0) | G35: =IFERROR(产品SKU!Q5,0) | H35: =IFERROR(过程品仓计算!F35*过程品仓计算!G35,0) | J35: 2 | K35: =IFERROR(IF(过程品仓计算!I35="",0,过程品仓计算!I35)*IF(过程品仓计算!J35="",0,过程品仓计算!J35),0) | L35: =IFERROR(MAX(过程品仓计算!H35,过程品仓计算!K35),0) | P35: =IFERROR(过程品仓计算!L35+IF(过程品仓计算!M35="",0,过程品仓计算!M35)+IF(过程品仓计算!N35="",0,过程品仓计算!N35)+IF(过程品仓计算!O35="",0,过程品仓计算!O35),0) | Q35: =IFERROR(CEILING(过程品仓计算!P35/MAX(产品SKU!M5,1),1)*参数设置!$C$13/MAX(参数设置!$C$14,1)/参数设置!$C$18*参数设置!$C$21,0)
A36: 4 | B36: 工序3后暂存（成品前） | C36: =IFERROR(产品SKU!B6,"") | D36: =IFERROR(产品SKU!D6,"") | E36: =IFERROR(产品SKU!G6,0) | F36: =IFERROR(过程品仓计算!E36/参数设置!$C$5,0) | G36: =IFERROR(产品SKU!Q6,0) | H36: =IFERROR(过程品仓计算!F36*过程品仓计算!G36,0) | J36: 2 | K36: =IFERROR(IF(过程品仓计算!I36="",0,过程品仓计算!I36)*IF(过程品仓计算!J36="",0,过程品仓计算!J36),0) | L36: =IFERROR(MAX(过程品仓计算!H36,过程品仓计算!K36),0) | P36: =IFERROR(过程品仓计算!L36+IF(过程品仓计算!M36="",0,过程品仓计算!M36)+IF(过程品仓计算!N36="",0,过程品仓计算!N36)+IF(过程品仓计算!O36="",0,过程品仓计算!O36),0) | Q36: =IFERROR(CEILING(过程品仓计算!P36/MAX(产品SKU!M6,1),1)*参数设置!$C$13/MAX(参数设置!$C$14,1)/参数设置!$C$18*参数设置!$C$21,0)
A37: 5 | B37: 工序3后暂存（成品前） | C37: =IFERROR(产品SKU!B7,"") | D37: =IFERROR(产品SKU!D7,"") | E37: =IFERROR(产品SKU!G7,0) | F37: =IFERROR(过程品仓计算!E37/参数设置!$C$5,0) | G37: =IFERROR(产品SKU!Q7,0) | H37: =IFERROR(过程品仓计算!F37*过程品仓计算!G37,0) | J37: 2 | K37: =IFERROR(IF(过程品仓计算!I37="",0,过程品仓计算!I37)*IF(过程品仓计算!J37="",0,过程品仓计算!J37),0) | L37: =IFERROR(MAX(过程品仓计算!H37,过程品仓计算!K37),0) | P37: =IFERROR(过程品仓计算!L37+IF(过程品仓计算!M37="",0,过程品仓计算!M37)+IF(过程品仓计算!N37="",0,过程品仓计算!N37)+IF(过程品仓计算!O37="",0,过程品仓计算!O37),0) | Q37: =IFERROR(CEILING(过程品仓计算!P37/MAX(产品SKU!M7,1),1)*参数设置!$C$13/MAX(参数设置!$C$14,1)/参数设置!$C$18*参数设置!$C$21,0)
A38: 6 | B38: 工序3后暂存（成品前） | C38: =IFERROR(产品SKU!B8,"") | D38: =IFERROR(产品SKU!D8,"") | E38: =IFERROR(产品SKU!G8,0) | F38: =IFERROR(过程品仓计算!E38/参数设置!$C$5,0) | G38: =IFERROR(产品SKU!Q8,0) | H38: =IFERROR(过程品仓计算!F38*过程品仓计算!G38,0) | J38: 2 | K38: =IFERROR(IF(过程品仓计算!I38="",0,过程品仓计算!I38)*IF(过程品仓计算!J38="",0,过程品仓计算!J38),0) | L38: =IFERROR(MAX(过程品仓计算!H38,过程品仓计算!K38),0) | P38: =IFERROR(过程品仓计算!L38+IF(过程品仓计算!M38="",0,过程品仓计算!M38)+IF(过程品仓计算!N38="",0,过程品仓计算!N38)+IF(过程品仓计算!O38="",0,过程品仓计算!O38),0) | Q38: =IFERROR(CEILING(过程品仓计算!P38/MAX(产品SKU!M8,1),1)*参数设置!$C$13/MAX(参数设置!$C$14,1)/参数设置!$C$18*参数设置!$C$21,0)
A39: 7 | B39: 工序3后暂存（成品前） | C39: =IFERROR(产品SKU!B9,"") | D39: =IFERROR(产品SKU!D9,"") | E39: =IFERROR(产品SKU!G9,0) | F39: =IFERROR(过程品仓计算!E39/参数设置!$C$5,0) | G39: =IFERROR(产品SKU!Q9,0) | H39: =IFERROR(过程品仓计算!F39*过程品仓计算!G39,0) | J39: 2 | K39: =IFERROR(IF(过程品仓计算!I39="",0,过程品仓计算!I39)*IF(过程品仓计算!J39="",0,过程品仓计算!J39),0) | L39: =IFERROR(MAX(过程品仓计算!H39,过程品仓计算!K39),0) | P39: =IFERROR(过程品仓计算!L39+IF(过程品仓计算!M39="",0,过程品仓计算!M39)+IF(过程品仓计算!N39="",0,过程品仓计算!N39)+IF(过程品仓计算!O39="",0,过程品仓计算!O39),0) | Q39: =IFERROR(CEILING(过程品仓计算!P39/MAX(产品SKU!M9,1),1)*参数设置!$C$13/MAX(参数设置!$C$14,1)/参数设置!$C$18*参数设置!$C$21,0)
A40: 8 | B40: 工序3后暂存（成品前） | C40: =IFERROR(产品SKU!B10,"") | D40: =IFERROR(产品SKU!D10,"") | E40: =IFERROR(产品SKU!G10,0) | F40: =IFERROR(过程品仓计算!E40/参数设置!$C$5,0) | G40: =IFERROR(产品SKU!Q10,0) | H40: =IFERROR(过程品仓计算!F40*过程品仓计算!G40,0) | J40: 2 | K40: =IFERROR(IF(过程品仓计算!I40="",0,过程品仓计算!I40)*IF(过程品仓计算!J40="",0,过程品仓计算!J40),0) | L40: =IFERROR(MAX(过程品仓计算!H40,过程品仓计算!K40),0) | P40: =IFERROR(过程品仓计算!L40+IF(过程品仓计算!M40="",0,过程品仓计算!M40)+IF(过程品仓计算!N40="",0,过程品仓计算!N40)+IF(过程品仓计算!O40="",0,过程品仓计算!O40),0) | Q40: =IFERROR(CEILING(过程品仓计算!P40/MAX(产品SKU!M10,1),1)*参数设置!$C$13/MAX(参数设置!$C$14,1)/参数设置!$C$18*参数设置!$C$21,0)
...

Sheet 成品仓计算
A1: 成品仓计算 — 设计库存量
A2: 公式：设计库存 = MAX(日需求×生产间隔, 日需求×目标库存天数, 最小生产批量) + 安全库存(日需求×安全天数) + 待检放行库存
A3: 行号 | B3: 产品编号/SKU | C3: 产品名称 | D3: 单位 | E3: 日需求量 [自动] | F3: 生产间隔 (天) [自动] | G3: 目标库存 天数 [自动] | H3: 最小生产 批量 [自动] | I3: 按生产间隔 计算库存 [自动] | J3: 按目标天数 计算库存 [自动] | K3: 设计基础 库存 =MAX(...) [自动] | L3: 安全库存 [自动] | M3: 待检放行 库存 | N3: 设计库存 合计 [自动] | O3: 估算占地 面积(m²) [自动]
A4: 1 | B4: =IFERROR(产品SKU!B3,"") | C4: =IFERROR(产品SKU!C3,"") | D4: =IFERROR(产品SKU!D3,"") | E4: =IFERROR(产品SKU!G3,0) | F4: =IFERROR(产品SKU!I3,0) | G4: =IFERROR(产品SKU!J3,0) | H4: =IFERROR(产品SKU!H3,0) | I4: =IFERROR(成品仓计算!E4*成品仓计算!F4,0) | J4: =IFERROR(成品仓计算!E4*成品仓计算!G4,0) | K4: =IFERROR(MAX(成品仓计算!I4,成品仓计算!J4,成品仓计算!H4),0) | L4: =IFERROR(成品仓计算!E4*产品SKU!K3*参数设置!$C$9,0) | N4: =IFERROR(成品仓计算!K4+成品仓计算!L4+IF(成品仓计算!M4="",0,成品仓计算!M4),0) | O4: =IFERROR(CEILING(成品仓计算!N4/MAX(产品SKU!M3,1),1)*参数设置!$C$13/MAX(参数设置!$C$14,1)/参数设置!$C$19*参数设置!$C$21,0)
A5: 2 | B5: =IFERROR(产品SKU!B4,"") | C5: =IFERROR(产品SKU!C4,"") | D5: =IFERROR(产品SKU!D4,"") | E5: =IFERROR(产品SKU!G4,0) | F5: =IFERROR(产品SKU!I4,0) | G5: =IFERROR(产品SKU!J4,0) | H5: =IFERROR(产品SKU!H4,0) | I5: =IFERROR(成品仓计算!E5*成品仓计算!F5,0) | J5: =IFERROR(成品仓计算!E5*成品仓计算!G5,0) | K5: =IFERROR(MAX(成品仓计算!I5,成品仓计算!J5,成品仓计算!H5),0) | L5: =IFERROR(成品仓计算!E5*产品SKU!K4*参数设置!$C$9,0) | N5: =IFERROR(成品仓计算!K5+成品仓计算!L5+IF(成品仓计算!M5="",0,成品仓计算!M5),0) | O5: =IFERROR(CEILING(成品仓计算!N5/MAX(产品SKU!M4,1),1)*参数设置!$C$13/MAX(参数设置!$C$14,1)/参数设置!$C$19*参数设置!$C$21,0)
A6: 3 | B6: =IFERROR(产品SKU!B5,"") | C6: =IFERROR(产品SKU!C5,"") | D6: =IFERROR(产品SKU!D5,"") | E6: =IFERROR(产品SKU!G5,0) | F6: =IFERROR(产品SKU!I5,0) | G6: =IFERROR(产品SKU!J5,0) | H6: =IFERROR(产品SKU!H5,0) | I6: =IFERROR(成品仓计算!E6*成品仓计算!F6,0) | J6: =IFERROR(成品仓计算!E6*成品仓计算!G6,0) | K6: =IFERROR(MAX(成品仓计算!I6,成品仓计算!J6,成品仓计算!H6),0) | L6: =IFERROR(成品仓计算!E6*产品SKU!K5*参数设置!$C$9,0) | N6: =IFERROR(成品仓计算!K6+成品仓计算!L6+IF(成品仓计算!M6="",0,成品仓计算!M6),0) | O6: =IFERROR(CEILING(成品仓计算!N6/MAX(产品SKU!M5,1),1)*参数设置!$C$13/MAX(参数设置!$C$14,1)/参数设置!$C$19*参数设置!$C$21,0)
A7: 4 | B7: =IFERROR(产品SKU!B6,"") | C7: =IFERROR(产品SKU!C6,"") | D7: =IFERROR(产品SKU!D6,"") | E7: =IFERROR(产品SKU!G6,0) | F7: =IFERROR(产品SKU!I6,0) | G7: =IFERROR(产品SKU!J6,0) | H7: =IFERROR(产品SKU!H6,0) | I7: =IFERROR(成品仓计算!E7*成品仓计算!F7,0) | J7: =IFERROR(成品仓计算!E7*成品仓计算!G7,0) | K7: =IFERROR(MAX(成品仓计算!I7,成品仓计算!J7,成品仓计算!H7),0) | L7: =IFERROR(成品仓计算!E7*产品SKU!K6*参数设置!$C$9,0) | N7: =IFERROR(成品仓计算!K7+成品仓计算!L7+IF(成品仓计算!M7="",0,成品仓计算!M7),0) | O7: =IFERROR(CEILING(成品仓计算!N7/MAX(产品SKU!M6,1),1)*参数设置!$C$13/MAX(参数设置!$C$14,1)/参数设置!$C$19*参数设置!$C$21,0)
A8: 5 | B8: =IFERROR(产品SKU!B7,"") | C8: =IFERROR(产品SKU!C7,"") | D8: =IFERROR(产品SKU!D7,"") | E8: =IFERROR(产品SKU!G7,0) | F8: =IFERROR(产品SKU!I7,0) | G8: =IFERROR(产品SKU!J7,0) | H8: =IFERROR(产品SKU!H7,0) | I8: =IFERROR(成品仓计算!E8*成品仓计算!F8,0) | J8: =IFERROR(成品仓计算!E8*成品仓计算!G8,0) | K8: =IFERROR(MAX(成品仓计算!I8,成品仓计算!J8,成品仓计算!H8),0) | L8: =IFERROR(成品仓计算!E8*产品SKU!K7*参数设置!$C$9,0) | N8: =IFERROR(成品仓计算!K8+成品仓计算!L8+IF(成品仓计算!M8="",0,成品仓计算!M8),0) | O8: =IFERROR(CEILING(成品仓计算!N8/MAX(产品SKU!M7,1),1)*参数设置!$C$13/MAX(参数设置!$C$14,1)/参数设置!$C$19*参数设置!$C$21,0)
A9: 6 | B9: =IFERROR(产品SKU!B8,"") | C9: =IFERROR(产品SKU!C8,"") | D9: =IFERROR(产品SKU!D8,"") | E9: =IFERROR(产品SKU!G8,0) | F9: =IFERROR(产品SKU!I8,0) | G9: =IFERROR(产品SKU!J8,0) | H9: =IFERROR(产品SKU!H8,0) | I9: =IFERROR(成品仓计算!E9*成品仓计算!F9,0) | J9: =IFERROR(成品仓计算!E9*成品仓计算!G9,0) | K9: =IFERROR(MAX(成品仓计算!I9,成品仓计算!J9,成品仓计算!H9),0) | L9: =IFERROR(成品仓计算!E9*产品SKU!K8*参数设置!$C$9,0) | N9: =IFERROR(成品仓计算!K9+成品仓计算!L9+IF(成品仓计算!M9="",0,成品仓计算!M9),0) | O9: =IFERROR(CEILING(成品仓计算!N9/MAX(产品SKU!M8,1),1)*参数设置!$C$13/MAX(参数设置!$C$14,1)/参数设置!$C$19*参数设置!$C$21,0)
A10: 7 | B10: =IFERROR(产品SKU!B9,"") | C10: =IFERROR(产品SKU!C9,"") | D10: =IFERROR(产品SKU!D9,"") | E10: =IFERROR(产品SKU!G9,0) | F10: =IFERROR(产品SKU!I9,0) | G10: =IFERROR(产品SKU!J9,0) | H10: =IFERROR(产品SKU!H9,0) | I10: =IFERROR(成品仓计算!E10*成品仓计算!F10,0) | J10: =IFERROR(成品仓计算!E10*成品仓计算!G10,0) | K10: =IFERROR(MAX(成品仓计算!I10,成品仓计算!J10,成品仓计算!H10),0) | L10: =IFERROR(成品仓计算!E10*产品SKU!K9*参数设置!$C$9,0) | N10: =IFERROR(成品仓计算!K10+成品仓计算!L10+IF(成品仓计算!M10="",0,成品仓计算!M10),0) | O10: =IFERROR(CEILING(成品仓计算!N10/MAX(产品SKU!M9,1),1)*参数设置!$C$13/MAX(参数设置!$C$14,1)/参数设置!$C$19*参数设置!$C$21,0)
A11: 8 | B11: =IFERROR(产品SKU!B10,"") | C11: =IFERROR(产品SKU!C10,"") | D11: =IFERROR(产品SKU!D10,"") | E11: =IFERROR(产品SKU!G10,0) | F11: =IFERROR(产品SKU!I10,0) | G11: =IFERROR(产品SKU!J10,0) | H11: =IFERROR(产品SKU!H10,0) | I11: =IFERROR(成品仓计算!E11*成品仓计算!F11,0) | J11: =IFERROR(成品仓计算!E11*成品仓计算!G11,0) | K11: =IFERROR(MAX(成品仓计算!I11,成品仓计算!J11,成品仓计算!H11),0) | L11: =IFERROR(成品仓计算!E11*产品SKU!K10*参数设置!$C$9,0) | N11: =IFERROR(成品仓计算!K11+成品仓计算!L11+IF(成品仓计算!M11="",0,成品仓计算!M11),0) | O11: =IFERROR(CEILING(成品仓计算!N11/MAX(产品SKU!M10,1),1)*参数设置!$C$13/MAX(参数设置!$C$14,1)/参数设置!$C$19*参数设置!$C$21,0)
A12: 9 | B12: =IFERROR(产品SKU!B11,"") | C12: =IFERROR(产品SKU!C11,"") | D12: =IFERROR(产品SKU!D11,"") | E12: =IFERROR(产品SKU!G11,0) | F12: =IFERROR(产品SKU!I11,0) | G12: =IFERROR(产品SKU!J11,0) | H12: =IFERROR(产品SKU!H11,0) | I12: =IFERROR(成品仓计算!E12*成品仓计算!F12,0) | J12: =IFERROR(成品仓计算!E12*成品仓计算!G12,0) | K12: =IFERROR(MAX(成品仓计算!I12,成品仓计算!J12,成品仓计算!H12),0) | L12: =IFERROR(成品仓计算!E12*产品SKU!K11*参数设置!$C$9,0) | N12: =IFERROR(成品仓计算!K12+成品仓计算!L12+IF(成品仓计算!M12="",0,成品仓计算!M12),0) | O12: =IFERROR(CEILING(成品仓计算!N12/MAX(产品SKU!M11,1),1)*参数设置!$C$13/MAX(参数设置!$C$14,1)/参数设置!$C$19*参数设置!$C$21,0)
A13: 10 | B13: =IFERROR(产品SKU!B12,"") | C13: =IFERROR(产品SKU!C12,"") | D13: =IFERROR(产品SKU!D12,"") | E13: =IFERROR(产品SKU!G12,0) | F13: =IFERROR(产品SKU!I12,0) | G13: =IFERROR(产品SKU!J12,0) | H13: =IFERROR(产品SKU!H12,0) | I13: =IFERROR(成品仓计算!E13*成品仓计算!F13,0) | J13: =IFERROR(成品仓计算!E13*成品仓计算!G13,0) | K13: =IFERROR(MAX(成品仓计算!I13,成品仓计算!J13,成品仓计算!H13),0) | L13: =IFERROR(成品仓计算!E13*产品SKU!K12*参数设置!$C$9,0) | N13: =IFERROR(成品仓计算!K13+成品仓计算!L13+IF(成品仓计算!M13="",0,成品仓计算!M13),0) | O13: =IFERROR(CEILING(成品仓计算!N13/MAX(产品SKU!M12,1),1)*参数设置!$C$13/MAX(参数设置!$C$14,1)/参数设置!$C$19*参数设置!$C$21,0)
A14: 11 | B14: =IFERROR(产品SKU!B13,"") | C14: =IFERROR(产品SKU!C13,"") | D14: =IFERROR(产品SKU!D13,"") | E14: =IFERROR(产品SKU!G13,0) | F14: =IFERROR(产品SKU!I13,0) | G14: =IFERROR(产品SKU!J13,0) | H14: =IFERROR(产品SKU!H13,0) | I14: =IFERROR(成品仓计算!E14*成品仓计算!F14,0) | J14: =IFERROR(成品仓计算!E14*成品仓计算!G14,0) | K14: =IFERROR(MAX(成品仓计算!I14,成品仓计算!J14,成品仓计算!H14),0) | L14: =IFERROR(成品仓计算!E14*产品SKU!K13*参数设置!$C$9,0) | N14: =IFERROR(成品仓计算!K14+成品仓计算!L14+IF(成品仓计算!M14="",0,成品仓计算!M14),0) | O14: =IFERROR(CEILING(成品仓计算!N14/MAX(产品SKU!M13,1),1)*参数设置!$C$13/MAX(参数设置!$C$14,1)/参数设置!$C$19*参数设置!$C$21,0)
A15: 12 | B15: =IFERROR(产品SKU!B14,"") | C15: =IFERROR(产品SKU!C14,"") | D15: =IFERROR(产品SKU!D14,"") | E15: =IFERROR(产品SKU!G14,0) | F15: =IFERROR(产品SKU!I14,0) | G15: =IFERROR(产品SKU!J14,0) | H15: =IFERROR(产品SKU!H14,0) | I15: =IFERROR(成品仓计算!E15*成品仓计算!F15,0) | J15: =IFERROR(成品仓计算!E15*成品仓计算!G15,0) | K15: =IFERROR(MAX(成品仓计算!I15,成品仓计算!J15,成品仓计算!H15),0) | L15: =IFERROR(成品仓计算!E15*产品SKU!K14*参数设置!$C$9,0) | N15: =IFERROR(成品仓计算!K15+成品仓计算!L15+IF(成品仓计算!M15="",0,成品仓计算!M15),0) | O15: =IFERROR(CEILING(成品仓计算!N15/MAX(产品SKU!M14,1),1)*参数设置!$C$13/MAX(参数设置!$C$14,1)/参数设置!$C$19*参数设置!$C$21,0)
A16: 合计 | N16: =SUM(N4:N15) | O16: =SUM(O4:O15)

Sheet 汇总
A1: 汇总 — 各仓库设计库存量与估算面积
A2: 仓库类别 | B2: 计算依据 | C2: 设计库存量 (合计) | D2: 库存单位 | E2: 设计托盘数 (合计) | F2: 估算占地 面积(m²) | G2: 含扩展余量 面积(m²) [自动] | H2: 备注
A3: 原料仓 | B3: MAX(日消耗×采购提前期, MOQ)×安全系数 + 安全库存 + 下批备料 + 退料 + 待检 | C3: =原料仓计算!M19 | D3: （各原料单位不同） | E3: =原料仓计算!O19 | F3: =原料仓计算!P19 | G3: =IFERROR(汇总!F3*参数设置!$C$21,0)
A4: 过程品仓 （工序1后） | B4: MAX(下游小时消耗×缓冲小时数, 批量×等待批次) + 待检 + 尾批 + 不良品 | C4: =过程品仓计算!P17 | D4: 件 | F4: =过程品仓计算!Q17 | G4: =IFERROR(汇总!F4*参数设置!$C$21,0)
A5: 过程品仓 （工序2后） | B5: MAX(下游小时消耗×缓冲小时数, 批量×等待批次) + 待检 + 尾批 + 不良品 | C5: =过程品仓计算!P31 | D5: 件 | F5: =过程品仓计算!Q31 | G5: =IFERROR(汇总!F5*参数设置!$C$21,0)
A6: 过程品仓 （工序3后） | B6: MAX(下游小时消耗×缓冲小时数, 批量×等待批次) + 待检 + 尾批 + 不良品 | C6: =过程品仓计算!P45 | D6: 件 | F6: =过程品仓计算!Q45 | G6: =IFERROR(汇总!F6*参数设置!$C$21,0)
A7: 过程品仓 合计 | B7: 见过程品仓计算!P46 | C7: =过程品仓计算!P46 | D7: 件 | F7: =过程品仓计算!Q46 | G7: =IFERROR(汇总!F7*参数设置!$C$21,0)
A8: 成品仓 | B8: MAX(日需求×生产间隔, 日需求×目标天数, 最小批量) + 安全库存 + 待检放行 | C8: =成品仓计算!N16 | D8: 件 | F8: =成品仓计算!O16 | G8: =IFERROR(汇总!F8*参数设置!$C$21,0)
A9: 三类仓库合计（不含辅助区域） | G9: =IFERROR(汇总!G3+汇总!G7+汇总!G8,0)
A11: ⚠ 上述面积为存储区估算，实际仓库还需加上：收发货区、质检区、不良品隔离区、退换货区、包装区、通道等辅助区域，通常再增加30%~50%的辅助面积。
A13: ★ 面积估算关键参数(可在[参数设置]工作表中修改)：
A14: 单托盘占地面积 | B14: =参数设置!C13&" m²"
A15: 地堆层数 | B15: =参数设置!C14&" 层"
A16: 原料仓面积利用率 | B16: =TEXT(参数设置!C17,"0.0%")
A17: 过程品仓面积利用率 | B17: =TEXT(参数设置!C18,"0.0%")
A18: 成品仓面积利用率 | B18: =TEXT(参数设置!C19,"0.0%")
A19: 扩展余量系数 | B19: =参数设置!C21
